Workbook

Sheet District_Name_Audit
A1: state code | B1: district code | C1: 17-19 | D1: 19-21 | E1: 21-23 | F1: 23/24 | G1: Name Changed? | H1: Missing Period?
A2: 1 | B2: 1 | C2: kupwara | D2: kupwara | E2: kupwara | F2: kupwara | G2: NO | H2: NO
A3: 1 | B3: 2 | C3: badgam | D3: badgam | E3: badgam | F3: badgam | G3: NO | H3: NO
A4: 1 | B4: 3 | C4: lehladakh | D4: lehladakh | G4: NO | H4: YES
A5: 1 | B5: 4 | C5: kargil | D5: kargil | G5: NO | H5: YES
A6: 1 | B6: 5 | C6: punch | D6: punch | E6: punch | F6: punch | G6: NO | H6: NO
A7: 1 | B7: 6 | C7: rajouri | D7: rajouri | E7: rajouri | F7: rajouri | G7: NO | H7: NO
A8: 1 | B8: 7 | C8: kathua | D8: kathua | E8: kathua | F8: kathua | G8: NO | H8: NO
A9: 1 | B9: 8 | C9: baramula | D9: baramula | E9: baramula | F9: baramula | G9: NO | H9: NO
A10: 1 | B10: 9 | C10: bandipore | D10: bandipore | E10: bandipore | F10: bandipore | G10: NO | H10: NO
A11: 1 | B11: 10 | C11: srinagar | D11: srinagar | E11: srinagar | F11: srinagar | G11: NO | H11: NO
A12: 1 | B12: 11 | C12: ganderbal | D12: ganderbal | E12: ganderbal | F12: ganderbal | G12: NO | H12: NO
A13: 1 | B13: 12 | C13: pulwama | D13: pulwama | E13: pulwama | F13: pulwama | G13: NO | H13: NO
A14: 1 | B14: 13 | C14: shupiyan | D14: shupiyan | E14: shupiyan | F14: shupiyan | G14: NO | H14: NO
A15: 1 | B15: 14 | C15: anantnag | D15: anantnag | E15: anantnag | F15: anantnag | G15: NO | H15: NO
A16: 1 | B16: 15 | C16: kulgam | D16: kulgam | E16: kulgam | F16: kulgam | G16: NO | H16: NO
A17: 1 | B17: 16 | C17: doda | D17: doda | E17: doda | F17: doda | G17: NO | H17: NO
... A295: 16 | B295: 4 | C295: northtripura | D295: northtripura | E295: northtripura | F295: northtripura | G295: NO | H295: NO
A296: 16 | B296: 5 | D296: unakoti | E296: unakoti | F296: unakoti | G296: NO | H296: YES
A297: 16 | B297: 6 | D297: khowai | E297: khowai | F297: khowai | G297: NO | H297: YES
A298: 16 | B298: 7 | D298: sepahijala | E298: sepahijala | F298: sepahijala | G298: NO | H298: YES
A299: 16 | B299: 8 | D299: gomati | E299: gomati | F299: gomati | G299: NO | H299: YES
A300: 17 | B300: 1 | C300: westgarohills | D300: westgarohills | E300: westgarohills | F300: westgarohills | G300: NO | H300: NO
A301: 17 | B301: 2 | C301: eastgarohills | D301: eastgarohills | E301: eastgarohills | F301: eastgarohills | G301: NO | H301: NO
A302: 17 | B302: 3 | C302: southgarohills | D302: southgarohills | E302: southgarohills | F302: southgarohills | G302: NO | H302: NO
A303: 17 | B303: 4 | C303: westkhasihills | D303: westkhasihills | E303: westkhasihills | F303: westkhasihills | G303: NO | H303: NO
A304: 17 | B304: 5 | C304: ribhoi | D304: ribhoi | E304: ribhoi | F304: ribhoi | G304: NO | H304: NO
A305: 17 | B305: 6 | C305: eastkhasihills | D305: eastkhasihills | E305: eastkhasihills | F305: eastkhasihills | G305: NO | H305: NO
A306: 17 | B306: 7 | C306: jaintiahills | D306: jaintiahills | E306: jaintiahills | F306: jaintiahills | G306: NO | H306: NO
A307: 18 | B307: 1 | C307: kokrajhar | D307: kokrajhar | E307: kokrajhar | F307: kokrajhar | G307: NO | H307: NO
A308: 18 | B308: 2 | C308: dhubri | D308: dhubri | E308: dhubri | F308: dhubri | G308: NO | H308: NO
A309: 18 | B309: 3 | C309: goalpara | D309: goalpara | E309: goalpara | F309: goalpara | G309: NO | H309: NO
A310: 18 | B310: 4 | C310: barpeta | D310: barpeta | E310: barpeta | F310: barpeta | G310: NO | H310: NO
A311: 18 | B311: 5 | C311: morigaon | D311: morigaon | E311: morigaon | F311: morigaon | G311: NO | H311: NO
... A333: 18 | B333: 27 | C333: udalguri | D333: udalguri | E333: udalguri | F333: udalguri | G333: NO | H333: NO
A334: 18 | B334: 28 | D334: hojai | E334: hojai | F334: hojai | G334: NO | H334: YES
A335: 18 | B335: 29 | D335: westkarbianglong | E335: westkarbianglong | F335: westkarbianglong | G335: NO | H335: YES
A336: 18 | B336: 30 | D336: charaideo | E336: charaideo | F336: charaideo | G336: NO | H336: YES
A337: 18 | B337: 31 | D337: southsalmaramankachar | E337: southsalmaramankachar | F337: southsalmaramankachar | G337: NO | H337: YES
A338: 18 | B338: 32 | D338: biswanath | E338: biswanath | F338: biswanath | G338: NO | H338: YES
...

Sheet District_Code_Audit (2)
A1: state code | B1: district name key | C1: 17-19 | D1: 19-21 | E1: 21-23 | F1: 23/24 | G1: Code Changed? | H1: Missing Period?
A2: 1 | B2: anantnag | C2: 14 | D2: 14 | E2: 14 | F2: 14 | G2: NO | H2: NO
A3: 1 | B3: badgam | C3: 2 | D3: 2 | E3: 2 | F3: 2 | G3: NO | H3: NO
A4: 1 | B4: bandipore | C4: 9 | D4: 9 | E4: 9 | F4: 9 | G4: NO | H4: NO
A5: 1 | B5: baramula | C5: 8 | D5: 8 | E5: 8 | F5: 8 | G5: NO | H5: NO
A6: 1 | B6: doda | C6: 16 | D6: 16 | E6: 16 | F6: 16 | G6: NO | H6: NO
A7: 1 | B7: ganderbal | C7: 11 | D7: 11 | E7: 11 | F7: 11 | G7: NO | H7: NO
A8: 1 | B8: jammu | C8: 21 | D8: 21 | E8: 21 | F8: 21 | G8: NO | H8: NO
A9: 1 | B9: kargil | C9: 4 | D9: 4 | G9: NO | H9: YES
A10: 1 | B10: kathua | C10: 7 | D10: 7 | E10: 7 | F10: 7 | G10: NO | H10: NO
A11: 1 | B11: kishtwar | C11: 18 | D11: 18 | E11: 18 | F11: 18 | G11: NO | H11: NO
A12: 1 | B12: kulgam | C12: 15 | D12: 15 | E12: 15 | F12: 15 | G12: NO | H12: NO
A13: 1 | B13: kupwara | C13: 1 | D13: 1 | E13: 1 | F13: 1 | G13: NO | H13: NO
A14: 1 | B14: lehladakh | C14: 3 | D14: 3 | G14: NO | H14: YES
A15: 1 | B15: pulwama | C15: 12 | D15: 12 | E15: 12 | F15: 12 | G15: NO | H15: NO
A16: 1 | B16: punch | C16: 5 | D16: 5 | E16: 5 | F16: 5 | G16: NO | H16: NO
A17: 1 | B17: rajouri | C17: 6 | D17: 6 | E17: 6 | F17: 6 | G17: NO | H17: NO
A18: 1 | B18: ramban | C18: 17 | D18: 17 | E18: 17 | F18: 17 | G18: NO | H18: NO
A19: 1 | B19: reasi | C19: 20 | D19: 20 | E19: 20 | F19: 20 | G19: NO | H19: NO
A20: 1 | B20: samba | C20: 22 | D20: 22 | E20: 22 | F20: 22 | G20: NO | H20: NO
A21: 1 | B21: shupiyan | C21: 13 | D21: 13 | E21: 13 | F21: 13 | G21: NO | H21: NO
A22: 1 | B22: srinagar | C22: 10 | D22: 10 | E22: 10 | F22: 10 | G22: NO | H22: NO
A23: 1 | B23: udhampur | C23: 19 | D23: 19 | E23: 19 | F23: 19 | G23: NO | H23: NO
A24: 2 | B24: bilaspur | C24: 8 | D24: 8 | E24: 8 | F24: 8 | G24: NO | H24: NO
A25: 2 | B25: chamba | C25: 1 | D25: 1 | E25: 1 | F25: 1 | G25: NO | H25: NO
A26: 2 | B26: hamirpur | C26: 6 | D26: 6 | E26: 6 | F26: 6 | G26: NO | H26: NO
... A92: 6 | B92: yamunanagar | C92: 3 | D92: 3 | E92: 3 | F92: 3 | G92: NO | H92: NO
A93: 7 | B93: central | D93: 6 | E93: 6 | F93: 6 | G93: NO | H93: YES
A94: 7 | B94: centraldelhi | C94: 6 | G94: NO | H94: YES
A95: 7 | B95: east | D95: 4 | E95: 4 | F95: 4 | G95: NO | H95: YES
A96: 7 | B96: eastdelhi | C96: 4 | G96: NO | H96: YES
A97: 7 | B97: newdelhi | C97: 5 | D97: 5 | E97: 5 | F97: 5 | G97: NO | H97: NO
A98: 7 | B98: north | D98: 2 | E98: 2 | F98: 2 | G98: NO | H98: YES
A99: 7 | B99: northdelhi | C99: 2 | G99: NO | H99: YES
A100: 7 | B100: northeast | D100: 3 | E100: 3 | F100: 3 | G100: NO | H100: YES
A101: 7 | B101: northeastdelhi | C101: 3 | G101: NO | H101: YES
A102: 7 | B102: northwest | D102: 1 | E102: 1 | F102: 1 | G102: NO | H102: YES
A103: 7 | B103: northwestdelhi | C103: 1 | G103: NO | H103: YES
A104: 7 | B104: south | D104: 9 | E104: 9 | F104: 9 | G104: NO | H104: YES
A105: 7 | B105: southdelhi | C105: 9 | G105: NO | H105: YES
...

Sheet State Audit
A1: State Code | B1: 16 | C1: District name → Code audit | M1: {=_xlfn._xlws.SORT(_xlfn.UNIQUE(tblDistrictCodeAuditFinal[state code]))} -> 1
M2: 2 | O2: state code | P2: district code | Q2: 17-19 | R2: 19-21 | S2: 21-23 | T2: 23/24 | U2: Name Changed? | V2: Missing Period? | Y2: state code | Z2: district name key | AA2: 17-19 | AB2: 19-21 | AC2: 21-23 | AD2: 23/24 | AE2: Code Changed? | AF2: Missing Period?
A3: state code | B3: district name key | C3: 17-19 | D3: 19-21 | E3: 21-23 | F3: 23/24 | G3: Code Changed? | H3: Missing Period? | M3: 3 | O3: {=_xlfn.LET( _xlpm.x,_xlfn._xlws.FILTER( tblDistrictCodeAuditFinal[], (tblDistrictCodeAuditFinal[Code Changed?]="YES")+ (tblDistrictCodeAuditFinal[Missing Period?]="YES"), "No issues found" ), IF(_xlpm.x="","",_xlpm.x) )} -> 1 | P3: kargil | Q3: 4 | R3: 4 | U3: NO | V3: YES | Y3: {=_xlfn.LET( _xlpm.x,_xlfn._xlws.FILTER( tblDistrictNameAuditFinal[], (INDEX(tblDistrictNameAuditFinal[],0,COLUMNS(tblDistrictNameAuditFinal[])-1)="YES")+ (INDEX(tblDistrictNameAuditFinal[],0,COLUMNS(tblDistrictNameAuditFinal[]))="YES"), "No issues found" ), IF(_xlpm.x="","",_xlpm.x) )} -> 1 | Z3: 3 | AA3: lehladakh | AB3: lehladakh | AE3: NO | AF3: YES
A4: {=_xlfn.LET( _xlpm.x,_xlfn._xlws.FILTER(tblDistrictCodeAuditFinal[],tblDistrictCodeAuditFinal[state code]=$B$1,"No districts found"), IF(_xlpm.x="","",_xlpm.x) )} -> 16 | B4: dhalai | C4: 3 | D4: 3 | E4: 3 | F4: 3 | G4: NO | H4: NO | M4: 4 | O4: 1 | P4: lehladakh | Q4: 3 | R4: 3 | U4: NO | V4: YES | Y4: 1 | Z4: 4 | AA4: kargil | AB4: kargil | AE4: NO | AF4: YES
A5: 16 | B5: gomati | D5: 8 | E5: 8 | F5: 8 | G5: NO | H5: YES | M5: 5 | O5: 7 | P5: central | R5: 6 | S5: 6 | T5: 6 | U5: NO | V5: YES | Y5: 7 | Z5: 1 | AA5: northwestdelhi | AB5: northwest | AC5: northwest | AD5: northwest | AE5: YES | AF5: NO
A6: 16 | B6: khowai | D6: 6 | E6: 6 | F6: 6 | G6: NO | H6: YES | M6: 6 | O6: 7 | P6: centraldelhi | Q6: 6 | U6: NO | V6: YES | Y6: 7 | Z6: 2 | AA6: northdelhi | AB6: north | AC6: north | AD6: north | AE6: YES | AF6: NO
A7: 16 | B7: northtripura | C7: 4 | D7: 4 | E7: 4 | F7: 4 | G7: NO | H7: NO | M7: 7 | O7: 7 | P7: east | R7: 4 | S7: 4 | T7: 4 | U7: NO | V7: YES | Y7: 7 | Z7: 3 | AA7: northeastdelhi | AB7: northeast | AC7: northeast | AD7: northeast | AE7: YES | AF7: NO
A8: 16 | B8: sepahijala | D8: 7 | E8: 7 | F8: 7 | G8: NO | H8: YES | M8: 8 | O8: 7 | P8: eastdelhi | Q8: 4 | U8: NO | V8: YES | Y8: 7 | Z8: 4 | AA8: eastdelhi | AB8: east | AC8: east | AD8: east | AE8: YES | AF8: NO
A9: 16 | B9: southtripura | C9: 2 | D9: 2 | E9: 2 | F9: 2 | G9: NO | H9: NO | M9: 9 | O9: 7 | P9: north | R9: 2 | S9: 2 | T9: 2 | U9: NO | V9: YES | Y9: 7 | Z9: 6 | AA9: centraldelhi | AB9: central | AC9: central | AD9: central | AE9: YES | AF9: NO
A10: 16 | B10: unakoti | D10: 5 | E10: 5 | F10: 5 | G10: NO | H10: YES | M10: 10 | O10: 7 | P10: northdelhi | Q10: 2 | U10: NO | V10: YES | Y10: 7 | Z10: 7 | AA10: westdelhi | AB10: west | AC10: west | AD10: west | AE10: YES | AF10: NO
A11: 16 | B11: westtripura | C11: 1 | D11: 1 | E11: 1 | F11: 1 | G11: NO | H11: NO | M11: 11 | O11: 7 | P11: northeast | R11: 3 | S11: 3 | T11: 3 | U11: NO | V11: YES | Y11: 7 | Z11: 8 | AA11: southwestdelhi | AB11: southwest | AC11: southwest | AD11: southwest | AE11: YES | AF11: NO
M12: 12 | O12: 7 | P12: northeastdelhi | Q12: 3 | U12: NO | V12: YES | Y12: 7 | Z12: 9 | AA12: southdelhi | AB12: south | AC12: south | AD12: south | AE12: YES | AF12: NO
M13: 13 | O13: 7 | P13: northwest | R13: 1 | S13: 1 | T13: 1 | U13: NO | V13: YES | Y13: 16 | Z13: 5 | AB13: unakoti | AC13: unakoti | AD13: unakoti | AE13: NO | AF13: YES
M14: 14 | O14: 7 | P14: northwestdelhi | Q14: 1 | U14: NO | V14: YES | Y14: 16 | Z14: 6 | AB14: khowai | AC14: khowai | AD14: khowai | AE14: NO | AF14: YES
M15: 15 | O15: 7 | P15: south | R15: 9 | S15: 9 | T15: 9 | U15: NO | V15: YES | Y15: 16 | Z15: 7 | AB15: sepahijala | AC15: sepahijala | AD15: sepahijala | AE15: NO | AF15: YES
M16: 16 | O16: 7 | P16: southdelhi | Q16: 9 | U16: NO | V16: YES | Y16: 16 | Z16: 8 | AB16: gomati | AC16: gomati | AD16: gomati | AE16: NO | AF16: YES
M17: 17 | O17: 7 | P17: southwest | R17: 8 | S17: 8 | T17: 8 | U17: NO | V17: YES | Y17: 18 | Z17: 28 | AB17: hojai | AC17: hojai | AD17: hojai | AE17: NO | AF17: YES
M18: 18 | O18: 7 | P18: southwestdelhi | Q18: 8 | U18: NO | V18: YES | Y18: 18 | Z18: 29 | AB18: westkarbianglong | AC18: westkarbianglong | AD18: westkarbianglong | AE18: NO | AF18: YES
M19: 19 | O19: 7 | P19: west | R19: 7 | S19: 7 | T19: 7 | U19: NO | V19: YES | Y19: 18 | Z19: 30 | AB19: charaideo | AC19: charaideo | AD19: charaideo | AE19: NO | AF19: YES
M20: 20 | O20: 7 | P20: westdelhi | Q20: 7 | U20: NO | V20: YES | Y20: 18 | Z20: 31 | AB20: southsalmaramankachar | AC20: southsalmaramankachar | AD20: southsalmaramankachar | AE20: NO | AF20: YES
M21: 21 | O21: 16 | P21: gomati | R21: 8 | S21: 8 | T21: 8 | U21: NO | V21: YES | Y21: 18 | Z21: 32 | AB21: biswanath | AC21: biswanath | AD21: biswanath | AE21: NO | AF21: YES
M22: 22 | O22: 16 | P22: khowai | R22: 6 | S22: 6 | T22: 6 | U22: NO | V22: YES | Y22: 18 | Z22: 33 | AB22: majuli | AC22: majuli | AD22: majuli | AE22: NO | AF22: YES
M23: 23 | O23: 16 | P23: sepahijala | R23: 7 | S23: 7 | T23: 7 | U23: NO | V23: YES | Y23: 19 | Z23: 9 | AA23: barddhaman | AB23: purbabarddhaman | AC23: purbabarddhaman | AD23: purbabarddhaman | AE23: YES | AF23: NO
M24: 24 | O24: 16 | P24: unakoti | R24: 5 | S24: 5 | T24: 5 | U24: NO | V24: YES | Y24: 19 | Z24: 20 | AB24: alipurduar | AC24: alipurduar | AD24: alipurduar | AE24: NO | AF24: YES
M25: 25 | O25: 18 | P25: biswanath | R25: 32 | S25: 32 | T25: 32 | U25: NO | V25: YES | Y25: 19 | Z25: 21 | AB25: kalimpong | AC25: kalimpong | AD25: kalimpong | AE25: NO | AF25: YES
M26: 26 | O26: 18 | P26: charaideo | R26: 30 | S26: 30 | T26: 30 | U26: NO | V26: YES | Y26: 19 | Z26: 22 | AB26: jhargram | AC26: jhargram | AD26: jhargram | AE26: NO | AF26: YES
M27: 27 | O27: 18 | P27: hojai | R27: 28 | S27: 28 | T27: 28 | U27: NO | V27: YES | Y27: 19 | Z27: 23 | AB27: paschimbarddhaman | AC27: paschimbarddhaman | AD27: paschimbarddhaman | AE27: NO | AF27: YES
M28: 28 | O28: 18 | P28: majuli | R28: 33 | S28: 33 | T28: 33 | U28: NO | V28: YES | Y28: 24 | Z28: 7 | AA28: ahmedabad | AB28: ahmadabad | AC28: ahmadabad | AD28: ahmadabad | AE28: YES | AF28: NO
M29: 29 | O29: 18 | P29: southsalmaramankachar | R29: 31 | S29: 31 | T29: 31 | U29: NO | V29: YES | Y29: 24 | Z29: 27 | AB29: arvalli | AC29: arvalli | AD29: arvalli | AE29: NO | AF29: YES
M30: 30 | O30: 18 | P30: westkarbianglong | R30: 29 | S30: 29 | T30: 29 | U30: NO | V30: YES | Y30: 24 | Z30: 28 | AB30: botad | AC30: botad | AD30: botad | AE30: NO | AF30: YES
M31: 31 | O31: 19 | P31: alipurduar | R31: 20 | S31: 20 | T31: 20 | U31: NO | V31: YES | Y31: 24 | Z31: 29 | AB31: chhotaudepur | AC31: chhotaudepur | AD31: chhotaudepur | AE31: NO | AF31: YES
M32: 32 | O32: 19 | P32: barddhaman | Q32: 9 | U32: NO | V32: YES | Y32: 24 | Z32: 30 | AB32: devbhumidwarka | AC32: devbhumidwarka | AD32: devbhumidwarka | AE32: NO | AF32: YES
M33: 33 | O33: 19 | P33: jhargram | R33: 22 | S33: 22 | T33: 22 | U33: NO | V33: YES | Y33: 24 | Z33: 31 | AB33: girsomnath | AC33: girsomnath | AD33: girsomnath | AE33: NO | AF33: YES
M34: 34 | O34: 19 | P34: kalimpong | R34: 21 | S34: 21 | T34: 21 | U34: NO | V34: YES | Y34: 24 | Z34: 32 | AB34: mahisagar | AC34: mahisagar | AD34: mahisagar | AE34: NO | AF34: YES
M35: 35 | O35: 19 | P35: paschimbarddhaman | R35: 23 | S35: 23 | T35: 23 | U35: NO | V35: YES | Y35: 24 | Z35: 33 | AB35: morbi | AC35: morbi | AD35: morbi | AE35: NO | AF35: YES
M36: 36 | O36: 19 | P36: purbabarddhaman | R36: 9 | S36: 9 | T36: 9 | U36: NO | V36: YES | Y36: 25 | Z36: 3 | AC36: dadra&nagarhaveli | AD36: dadra&nagarhaveli | AE36: NO | AF36: YES
M37: 37 | O37: 24 | P37: ahmadabad | R37: 7 | S37: 7 | T37: 7 | U37: NO | V37: YES | Y37: 26 | Z37: 1 | AA37: dadra&nagarhaveli | AB37: dadra&nagarhaveli | AE37: NO | AF37: YES
O38: 24 | P38: ahmedabad | Q38: 7 | U38: NO | V38: YES | Y38: 27 | Z38: 23 | AA38: mumbai | AE38: NO | AF38: YES
A39: state code | B39: district code | C39: 17-19 | D39: 19-21 | E39: 21-23 | F39: 23/24 | G39: Name Changed? | H39: Missing Period? | O39: 24 | P39: arvalli | R39: 27 | S39: 27 | T39: 27 | U39: NO | V39: YES | Y39: 32 | Z39: 1 | AA39: kasaragod | AB39: kasaragode | AC39: kasaragode | AD39: kasaragode | AE39: YES | AF39: NO
A40: District code → name audit | O40: 24 | P40: botad | R40: 28 | S40: 28 | T40: 28 | U40: NO | V40: YES | Y40: 36 | Z40: 2 | AA40: nizamabad | AB40: komarambheem | AC40: komarambheem | AD40: komarambheem | AE40: YES | AF40: NO
...

Sheet District_Crosswalk_Long
A1: Index | B1: Period | C1: state code | D1: state name | E1: district code | F1: district name | G1: district name clean | H1: district name key
A2: 11 | B2: 17-19 | C2: 1 | D2: Jammu & Kashmir | E2: 1 | F2: Kupwara | G2: kupwara | H2: kupwara
A3: 1 | B3: 19-21 | C3: 1 | D3: JAMMU & KASHMIR | E3: 1 | F3: Kupwara | G3: kupwara | H3: kupwara
A4: 1 | B4: 21-23 | C4: 1 | D4: JAMMU & KASHMIR | E4: 1 | F4: Kupwara | G4: kupwara | H4: kupwara
A5: 1 | B5: 23/24 | C5: 1 | D5: JAMMU & KASHMIR | E5: 1 | F5: Kupwara | G5: kupwara | H5: kupwara
A6: 12 | B6: 17-19 | C6: 1 | D6: Jammu & Kashmir | E6: 2 | F6: Badgam | G6: badgam | H6: badgam
A7: 2 | B7: 19-21 | C7: 1 | D7: JAMMU & KASHMIR | E7: 2 | F7: Badgam | G7: badgam | H7: badgam
A8: 2 | B8: 21-23 | C8: 1 | D8: JAMMU & KASHMIR | E8: 2 | F8: Badgam | G8: badgam | H8: badgam
A9: 2 | B9: 23/24 | C9: 1 | D9: JAMMU & KASHMIR | E9: 2 | F9: Badgam | G9: badgam | H9: badgam
A10: 21 | B10: 17-19 | C10: 1 | D10: Jammu & Kashmir | E10: 3 | F10: Leh (Ladakh) | G10: leh (ladakh) | H10: lehladakh
A11: 3 | B11: 19-21 | C11: 1 | D11: JAMMU & KASHMIR | E11: 3 | F11: Leh(Ladakh) | G11: leh(ladakh) | H11: lehladakh
A12: 22 | B12: 17-19 | C12: 1 | D12: Jammu & Kashmir | E12: 4 | F12: Kargil | G12: kargil | H12: kargil
A13: 4 | B13: 19-21 | C13: 1 | D13: JAMMU & KASHMIR | E13: 4 | F13: Kargil | G13: kargil | H13: kargil
... A2734: 694 | B2734: 23/24 | C2734: 37 | D2734: LADAKH | E2734: 2 | F2734: Kargil | G2734: kargil | H2734: kargil

Sheet District Names
A1: state code | B1: state name | C1: 17-19 | D1: 19-21 | E1: 21-23 | F1: 24 | G1: 25 | H1: Changed?
A2: {=_xlfn._xlws.SORT(_xlfn.UNIQUE(_xlfn.VSTACK('Raw Data'!A699:A1001,'Raw Data'!F5:F1001,'Raw Data'!K5:K1001,'Raw Data'!P5:P1001,'Raw Data'!U4:U1001)))} -> 1 | B2: =_xlfn.XLOOKUP(A2,'Raw Data'!$A$699:$A$1001,'Raw Data'!$B$699:$B$1001,"") | C2: =COUNTIF('Raw Data'!$U$4:$U$1001,A2) -> 0 | D2: =COUNTIF('Raw Data'!$P$5:$P$1001,A2) -> 20 | E2: =COUNTIF('Raw Data'!$K$5:$K$1001,A2) -> 20 | F2: =COUNTIF('Raw Data'!$F$5:$F$1001,A2) -> 18 | G2: =COUNTIF('Raw Data'!$A$699:$A$1001,A2) -> 0 | H2: =IF(MAX(C2:G2)=MIN(C2:G2),"No","YES") -> YES | I2: Jammu and Kashmir
A3: 2 | B3: =_xlfn.XLOOKUP(A3,'Raw Data'!$A$699:$A$1001,'Raw Data'!$B$699:$B$1001,"") | C3: =COUNTIF('Raw Data'!$U$4:$U$1001,A3) -> 0 | D3: =COUNTIF('Raw Data'!$P$5:$P$1001,A3) -> 12 | E3: =COUNTIF('Raw Data'!$K$5:$K$1001,A3) -> 12 | F3: =COUNTIF('Raw Data'!$F$5:$F$1001,A3) -> 12 | G3: =COUNTIF('Raw Data'!$A$699:$A$1001,A3) -> 0 | H3: =IF(MAX(C3:G3)=MIN(C3:G3),"No","YES") -> YES
A4: 3 | B4: =_xlfn.XLOOKUP(A4,'Raw Data'!$A$699:$A$1001,'Raw Data'!$B$699:$B$1001,"") | C4: =COUNTIF('Raw Data'!$U$4:$U$1001,A4) -> 0 | D4: =COUNTIF('Raw Data'!$P$5:$P$1001,A4) -> 22 | E4: =COUNTIF('Raw Data'!$K$5:$K$1001,A4) -> 22 | F4: =COUNTIF('Raw Data'!$F$5:$F$1001,A4) -> 22 | G4: =COUNTIF('Raw Data'!$A$699:$A$1001,A4) -> 0 | H4: =IF(MAX(C4:G4)=MIN(C4:G4),"No","YES") -> YES
A5: 4 | B5: =_xlfn.XLOOKUP(A5,'Raw Data'!$A$699:$A$1001,'Raw Data'!$B$699:$B$1001,"") | C5: =COUNTIF('Raw Data'!$U$4:$U$1001,A5) -> 0 | D5: =COUNTIF('Raw Data'!$P$5:$P$1001,A5) -> 1 | E5: =COUNTIF('Raw Data'!$K$5:$K$1001,A5) -> 1 | F5: =COUNTIF('Raw Data'!$F$5:$F$1001,A5) -> 1 | G5: =COUNTIF('Raw Data'!$A$699:$A$1001,A5) -> 0 | H5: =IF(MAX(C5:G5)=MIN(C5:G5),"No","YES") -> YES
A6: 5 | B6: =_xlfn.XLOOKUP(A6,'Raw Data'!$A$699:$A$1001,'Raw Data'!$B$699:$B$1001,"") | C6: =COUNTIF('Raw Data'!$U$4:$U$1001,A6) -> 0 | D6: =COUNTIF('Raw Data'!$P$5:$P$1001,A6) -> 13 | E6: =COUNTIF('Raw Data'!$K$5:$K$1001,A6) -> 13 | F6: =COUNTIF('Raw Data'!$F$5:$F$1001,A6) -> 13 | G6: =COUNTIF('Raw Data'!$A$699:$A$1001,A6) -> 0 | H6: =IF(MAX(C6:G6)=MIN(C6:G6),"No","YES") -> YES
A7: 6 | B7: =_xlfn.XLOOKUP(A7,'Raw Data'!$A$699:$A$1001,'Raw Data'!$B$699:$B$1001,"") | C7: =COUNTIF('Raw Data'!$U$4:$U$1001,A7) -> 0 | D7: =COUNTIF('Raw Data'!$P$5:$P$1001,A7) -> 21 | E7: =COUNTIF('Raw Data'!$K$5:$K$1001,A7) -> 21 | F7: =COUNTIF('Raw Data'!$F$5:$F$1001,A7) -> 21 | G7: =COUNTIF('Raw Data'!$A$699:$A$1001,A7) -> 0 | H7: =IF(MAX(C7:G7)=MIN(C7:G7),"No","YES") -> YES | I7: Tripura
A8: 7 | B8: =_xlfn.XLOOKUP(A8,'Raw Data'!$A$699:$A$1001,'Raw Data'!$B$699:$B$1001,"") | C8: =COUNTIF('Raw Data'!$U$4:$U$1001,A8) -> 0 | D8: =COUNTIF('Raw Data'!$P$5:$P$1001,A8) -> 9 | E8: =COUNTIF('Raw Data'!$K$5:$K$1001,A8) -> 9 | F8: =COUNTIF('Raw Data'!$F$5:$F$1001,A8) -> 9 | G8: =COUNTIF('Raw Data'!$A$699:$A$1001,A8) -> 0 | H8: =IF(MAX(C8:G8)=MIN(C8:G8),"No","YES") -> YES | I8: Assam
A9: 8 | B9: =_xlfn.XLOOKUP(A9,'Raw Data'!$A$699:$A$1001,'Raw Data'!$B$699:$B$1001,"") | C9: =COUNTIF('Raw Data'!$U$4:$U$1001,A9) -> 0 | D9: =COUNTIF('Raw Data'!$P$5:$P$1001,A9) -> 33 | E9: =COUNTIF('Raw Data'!$K$5:$K$1001,A9) -> 33 | F9: =COUNTIF('Raw Data'!$F$5:$F$1001,A9) -> 33 | G9: =COUNTIF('Raw Data'!$A$699:$A$1001,A9) -> 0 | H9: =IF(MAX(C9:G9)=MIN(C9:G9),"No","YES") -> YES | I9: West Bengal
A10: 9 | B10: =_xlfn.XLOOKUP(A10,'Raw Data'!$A$699:$A$1001,'Raw Data'!$B$699:$B$1001,"") | C10: =COUNTIF('Raw Data'!$U$4:$U$1001,A10) -> 0 | D10: =COUNTIF('Raw Data'!$P$5:$P$1001,A10) -> 71 | E10: =COUNTIF('Raw Data'!$K$5:$K$1001,A10) -> 71 | F10: =COUNTIF('Raw Data'!$F$5:$F$1001,A10) -> 71 | G10: =COUNTIF('Raw Data'!$A$699:$A$1001,A10) -> 0 | H10: =IF(MAX(C10:G10)=MIN(C10:G10),"No","YES") -> YES | I10: Gujarat
A11: 10 | B11: =_xlfn.XLOOKUP(A11,'Raw Data'!$A$699:$A$1001,'Raw Data'!$B$699:$B$1001,"") | C11: =COUNTIF('Raw Data'!$U$4:$U$1001,A11) -> 0 | D11: =COUNTIF('Raw Data'!$P$5:$P$1001,A11) -> 38 | E11: =COUNTIF('Raw Data'!$K$5:$K$1001,A11) -> 38 | F11: =COUNTIF('Raw Data'!$F$5:$F$1001,A11) -> 38 | G11: =COUNTIF('Raw Data'!$A$699:$A$1001,A11) -> 0 | H11: =IF(MAX(C11:G11)=MIN(C11:G11),"No","YES") -> YES | I11: Dadra and Nagar Haveli and Daman and Diu
A12: 11 | B12: =_xlfn.XLOOKUP(A12,'Raw Data'!$A$699:$A$1001,'Raw Data'!$B$699:$B$1001,"") | C12: =COUNTIF('Raw Data'!$U$4:$U$1001,A12) -> 0 | D12: =COUNTIF('Raw Data'!$P$5:$P$1001,A12) -> 4 | E12: =COUNTIF('Raw Data'!$K$5:$K$1001,A12) -> 4 | F12: =COUNTIF('Raw Data'!$F$5:$F$1001,A12) -> 4 | G12: =COUNTIF('Raw Data'!$A$699:$A$1001,A12) -> 0 | H12: =IF(MAX(C12:G12)=MIN(C12:G12),"No","YES") -> YES | I12: Telangana
A13: 12 | B13: =_xlfn.XLOOKUP(A13,'Raw Data'!$A$699:$A$1001,'Raw Data'!$B$699:$B$1001,"") | C13: =COUNTIF('Raw Data'!$U$4:$U$1001,A13) -> 0 | D13: =COUNTIF('Raw Data'!$P$5:$P$1001,A13) -> 16 | E13: =COUNTIF('Raw Data'!$K$5:$K$1001,A13) -> 16 | F13: =COUNTIF('Raw Data'!$F$5:$F$1001,A13) -> 16 | G13: =COUNTIF('Raw Data'!$A$699:$A$1001,A13) -> 0 | H13: =IF(MAX(C13:G13)=MIN(C13:G13),"No","YES") -> YES | I13: Maharashtra
A14: 13 | B14: =_xlfn.XLOOKUP(A14,'Raw Data'!$A$699:$A$1001,'Raw Data'!$B$699:$B$1001,"") | C14: =COUNTIF('Raw Data'!$U$4:$U$1001,A14) -> 0 | D14: =COUNTIF('Raw Data'!$P$5:$P$1001,A14) -> 11 | E14: =COUNTIF('Raw Data'!$K$5:$K$1001,A14) -> 11 | F14: =COUNTIF('Raw Data'!$F$5:$F$1001,A14) -> 11 | G14: =COUNTIF('Raw Data'!$A$699:$A$1001,A14) -> 0 | H14: =IF(MAX(C14:G14)=MIN(C14:G14),"No","YES") -> YES
A15: 14 | B15: =_xlfn.XLOOKUP(A15,'Raw Data'!$A$699:$A$1001,'Raw Data'!$B$699:$B$1001,"") | C15: =COUNTIF('Raw Data'!$U$4:$U$1001,A15) -> 0 | D15: =COUNTIF('Raw Data'!$P$5:$P$1001,A15) -> 9 | E15: =COUNTIF('Raw Data'!$K$5:$K$1001,A15) -> 9 | F15: =COUNTIF('Raw Data'!$F$5:$F$1001,A15) -> 9 | G15: =COUNTIF('Raw Data'!$A$699:$A$1001,A15) -> 0 | H15: =IF(MAX(C15:G15)=MIN(C15:G15),"No","YES") -> YES
A16: 15 | B16: =_xlfn.XLOOKUP(A16,'Raw Data'!$A$699:$A$1001,'Raw Data'!$B$699:$B$1001,"") | C16: =COUNTIF('Raw Data'!$U$4:$U$1001,A16) -> 0 | D16: =COUNTIF('Raw Data'!$P$5:$P$1001,A16) -> 8 | E16: =COUNTIF('Raw Data'!$K$5:$K$1001,A16) -> 8 | F16: =COUNTIF('Raw Data'!$F$5:$F$1001,A16) -> 8 | G16: =COUNTIF('Raw Data'!$A$699:$A$1001,A16) -> 0 | H16: =IF(MAX(C16:G16)=MIN(C16:G16),"No","YES") -> YES
A17: 16 | B17: =_xlfn.XLOOKUP(A17,'Raw Data'!$A$699:$A$1001,'Raw Data'!$B$699:$B$1001,"") | C17: =COUNTIF('Raw Data'!$U$4:$U$1001,A17) -> 0 | D17: =COUNTIF('Raw Data'!$P$5:$P$1001,A17) -> 4 | E17: =COUNTIF('Raw Data'!$K$5:$K$1001,A17) -> 8 | F17: =COUNTIF('Raw Data'!$F$5:$F$1001,A17) -> 8 | G17: =COUNTIF('Raw Data'!$A$699:$A$1001,A17) -> 0 | H17: =IF(MAX(C17:G17)=MIN(C17:G17),"No","YES") -> YES
A18: 17 | B18: =_xlfn.XLOOKUP(A18,'Raw Data'!$A$699:$A$1001,'Raw Data'!$B$699:$B$1001,"") | C18: =COUNTIF('Raw Data'!$U$4:$U$1001,A18) -> 0 | D18: =COUNTIF('Raw Data'!$P$5:$P$1001,A18) -> 7 | E18: =COUNTIF('Raw Data'!$K$5:$K$1001,A18) -> 7 | F18: =COUNTIF('Raw Data'!$F$5:$F$1001,A18) -> 7 | G18: =COUNTIF('Raw Data'!$A$699:$A$1001,A18) -> 0 | H18: =IF(MAX(C18:G18)=MIN(C18:G18),"No","YES") -> YES
A19: 18 | B19: =_xlfn.XLOOKUP(A19,'Raw Data'!$A$699:$A$1001,'Raw Data'!$B$699:$B$1001,"") | C19: =COUNTIF('Raw Data'!$U$4:$U$1001,A19) -> 0 | D19: =COUNTIF('Raw Data'!$P$5:$P$1001,A19) -> 27 | E19: =COUNTIF('Raw Data'!$K$5:$K$1001,A19) -> 33 | F19: =COUNTIF('Raw Data'!$F$5:$F$1001,A19) -> 33 | G19: =COUNTIF('Raw Data'!$A$699:$A$1001,A19) -> 0 | H19: =IF(MAX(C19:G19)=MIN(C19:G19),"No","YES") -> YES
A20: 19 | B20: =_xlfn.XLOOKUP(A20,'Raw Data'!$A$699:$A$1001,'Raw Data'!$B$699:$B$1001,"") | C20: =COUNTIF('Raw Data'!$U$4:$U$1001,A20) -> 0 | D20: =COUNTIF('Raw Data'!$P$5:$P$1001,A20) -> 19 | E20: =COUNTIF('Raw Data'!$K$5:$K$1001,A20) -> 23 | F20: =COUNTIF('Raw Data'!$F$5:$F$1001,A20) -> 23 | G20: =COUNTIF('Raw Data'!$A$699:$A$1001,A20) -> 0 | H20: =IF(MAX(C20:G20)=MIN(C20:G20),"No","YES") -> YES
A21: 20 | B21: =_xlfn.XLOOKUP(A21,'Raw Data'!$A$699:$A$1001,'Raw Data'!$B$699:$B$1001,"") | C21: =COUNTIF('Raw Data'!$U$4:$U$1001,A21) -> 0 | D21: =COUNTIF('Raw Data'!$P$5:$P$1001,A21) -> 24 | E21: =COUNTIF('Raw Data'!$K$5:$K$1001,A21) -> 24 | F21: =COUNTIF('Raw Data'!$F$5:$F$1001,A21) -> 24 | G21: =COUNTIF('Raw Data'!$A$699:$A$1001,A21) -> 0 | H21: =IF(MAX(C21:G21)=MIN(C21:G21),"No","YES") -> YES
A22: 21 | B22: =_xlfn.XLOOKUP(A22,'Raw Data'!$A$699:$A$1001,'Raw Data'!$B$699:$B$1001,"") | C22: =COUNTIF('Raw Data'!$U$4:$U$1001,A22) -> 0 | D22: =COUNTIF('Raw Data'!$P$5:$P$1001,A22) -> 30 | E22: =COUNTIF('Raw Data'!$K$5:$K$1001,A22) -> 30 | F22: =COUNTIF('Raw Data'!$F$5:$F$1001,A22) -> 30 | G22: =COUNTIF('Raw Data'!$A$699:$A$1001,A22) -> 0 | H22: =IF(MAX(C22:G22)=MIN(C22:G22),"No","YES") -> YES
A23: 22 | B23: =_xlfn.XLOOKUP(A23,'Raw Data'!$A$699:$A$1001,'Raw Data'!$B$699:$B$1001,"") | C23: =COUNTIF('Raw Data'!$U$4:$U$1001,A23) -> 0 | D23: =COUNTIF('Raw Data'!$P$5:$P$1001,A23) -> 27 | E23: =COUNTIF('Raw Data'!$K$5:$K$1001,A23) -> 27 | F23: =COUNTIF('Raw Data'!$F$5:$F$1001,A23) -> 27 | G23: =COUNTIF('Raw Data'!$A$699:$A$1001,A23) -> 0 | H23: =IF(MAX(C23:G23)=MIN(C23:G23),"No","YES") -> YES
A24: 23 | B24: =_xlfn.XLOOKUP(A24,'Raw Data'!$A$699:$A$1001,'Raw Data'!$B$699:$B$1001,"") | C24: =COUNTIF('Raw Data'!$U$4:$U$1001,A24) -> 0 | D24: =COUNTIF('Raw Data'!$P$5:$P$1001,A24) -> 50 | E24: =COUNTIF('Raw Data'!$K$5:$K$1001,A24) -> 50 | F24: =COUNTIF('Raw Data'!$F$5:$F$1001,A24) -> 50 | G24: =COUNTIF('Raw Data'!$A$699:$A$1001,A24) -> 0 | H24: =IF(MAX(C24:G24)=MIN(C24:G24),"No","YES") -> YES
A25: 24 | B25: =_xlfn.XLOOKUP(A25,'Raw Data'!$A$699:$A$1001,'Raw Data'!$B$699:$B$1001,"") | C25: =COUNTIF('Raw Data'!$U$4:$U$1001,A25) -> 0 | D25: =COUNTIF('Raw Data'!$P$5:$P$1001,A25) -> 26 | E25: =COUNTIF('Raw Data'!$K$5:$K$1001,A25) -> 33 | F25: =COUNTIF('Raw Data'!$F$5:$F$1001,A25) -> 33 | G25: =COUNTIF('Raw Data'!$A$699:$A$1001,A25) -> 0 | H25: =IF(MAX(C25:G25)=MIN(C25:G25),"No","YES") -> YES
... A37: 36 | B37: =_xlfn.XLOOKUP(A37,'Raw Data'!$A$699:$A$1001,'Raw Data'!$B$699:$B$1001,"") | C37: =COUNTIF('Raw Data'!$U$4:$U$1001,A37) -> 0 | D37: =COUNTIF('Raw Data'!$P$5:$P$1001,A37) -> 10 | E37: =COUNTIF('Raw Data'!$K$5:$K$1001,A37) -> 33 | F37: =COUNTIF('Raw Data'!$F$5:$F$1001,A37) -> 33 | G37: =COUNTIF('Raw Data'!$A$699:$A$1001,A37) -> 0 | H37: =IF(MAX(C37:G37)=MIN(C37:G37),"No","YES") -> YES
A38: 37 | B38: =_xlfn.XLOOKUP(A38,'Raw Data'!$A$699:$A$1001,'Raw Data'!$B$699:$B$1001,"") | C38: =COUNTIF('Raw Data'!$U$4:$U$1001,A38) -> 0 | D38: =COUNTIF('Raw Data'!$P$5:$P$1001,A38) -> 0
A39: 0 | B39: =_xlfn.XLOOKUP(A39,'Raw Data'!$A$699:$A$1001,'Raw Data'!$B$699:$B$1001,"") | C39: =COUNTIF('Raw Data'!$U$4:$U$1001,A39) -> 0

Sheet Raw Data
A1: 23/24 | F1: 21-23 | K1: 19-21 | P1: 17-19 | T1: Column20 | U1: Column21 | V1: Column22 | W1: Column23 | X1: Column24
A2: State Code | B2: State Name | C2: DISTRICT CODE | D2: DISTRICT NAME | F2: State Code | G2: State Name | H2: DISTRICT CODE | I2: DISTRICT NAME | K2: State Code | L2: State Name | M2: DISTRICT CODE | N2: DISTRICT NAME | P2: State Code | Q2: State name | R2: District Code | S2: District Name
A3: 1 | B3: JAMMU & KASHMIR | C3: 13 | D3: Shupiyan | F3: 1 | G3: JAMMU & KASHMIR | H3: 13 | I3: Shupiyan | K3: 1 | L3: JAMMU & KASHMIR | M3: 11 | N3: Ganderbal | P3: 1 | Q3: Jammu & Kashmir | R3: 1 | S3: Kupwara
A4: 1 | B4: JAMMU & KASHMIR | C4: 14 | D4: Anantnag | F4: 1 | G4: JAMMU & KASHMIR | H4: 14 | I4: Anantnag | K4: 1 | L4: JAMMU & KASHMIR | M4: 12 | N4: Pulwama | P4: 1 | Q4: Jammu & Kashmir | R4: 2 | S4: Badgam
A5: 1 | B5: JAMMU & KASHMIR | C5: 6 | D5: Rajouri | F5: 1 | G5: JAMMU & KASHMIR | H5: 6 | I5: Rajouri | K5: 1 | L5: JAMMU & KASHMIR | M5: 4 | N5: Kargil | P5: 1 | Q5: Jammu & Kashmir | R5: 5 | S5: Punch
A6: 1 | B6: JAMMU & KASHMIR | C6: 7 | D6: Kathua | F6: 1 | G6: JAMMU & KASHMIR | H6: 7 | I6: Kathua | K6: 1 | L6: JAMMU & KASHMIR | M6: 5 | N6: Punch | P6: 1 | Q6: Jammu & Kashmir | R6: 6 | S6: Rajouri
A7: 1 | B7: JAMMU & KASHMIR | C7: 1 | D7: Kupwara | F7: 1 | G7: JAMMU & KASHMIR | H7: 1 | I7: Kupwara | K7: 1 | L7: JAMMU & KASHMIR | M7: 1 | N7: Kupwara | P7: 1 | Q7: Jammu & Kashmir | R7: 7 | S7: Kathua
A8: 1 | B8: JAMMU & KASHMIR | C8: 15 | D8: Kulgam | F8: 1 | G8: JAMMU & KASHMIR | H8: 15 | I8: Kulgam | K8: 1 | L8: JAMMU & KASHMIR | M8: 13 | N8: Shupiyan | P8: 1 | Q8: Jammu & Kashmir | R8: 8 | S8: Baramula
A9: 1 | B9: JAMMU & KASHMIR | C9: 16 | D9: Doda | F9: 1 | G9: JAMMU & KASHMIR | H9: 16 | I9: Doda | K9: 1 | L9: JAMMU & KASHMIR | M9: 14 | N9: Anantnag | P9: 1 | Q9: Jammu & Kashmir | R9: 9 | S9: Bandipore
A10: 1 | B10: JAMMU & KASHMIR | C10: 17 | D10: Ramban | F10: 1 | G10: JAMMU & KASHMIR | H10: 17 | I10: Ramban | K10: 1 | L10: JAMMU & KASHMIR | M10: 15 | N10: Kulgam | P10: 1 | Q10: Jammu & Kashmir | R10: 10 | S10: Srinagar
A11: 1 | B11: JAMMU & KASHMIR | C11: 18 | D11: Kishtwar | F11: 1 | G11: JAMMU & KASHMIR | H11: 18 | I11: Kishtwar | K11: 1 | L11: JAMMU & KASHMIR | M11: 16 | N11: Doda | P11: 1 | Q11: Jammu & Kashmir | R11: 11 | S11: Ganderbal
A12: 1 | B12: JAMMU & KASHMIR | C12: 19 | D12: Udhampur | F12: 1 | G12: JAMMU & KASHMIR | H12: 19 | I12: Udhampur | K12: 1 | L12: JAMMU & KASHMIR | M12: 17 | N12: Ramban | P12: 1 | Q12: Jammu & Kashmir | R12: 12 | S12: Pulwama
A13: 1 | B13: JAMMU & KASHMIR | C13: 20 | D13: Reasi | F13: 1 | G13: JAMMU & KASHMIR | H13: 20 | I13: Reasi | K13: 1 | L13: JAMMU & KASHMIR | M13: 18 | N13: Kishtwar | P13: 1 | Q13: Jammu & Kashmir | R13: 13 | S13: Shupiyan
A14: 1 | B14: JAMMU & KASHMIR | C14: 21 | D14: Jammu | F14: 1 | G14: JAMMU & KASHMIR | H14: 21 | I14: Jammu | K14: 1 | L14: JAMMU & KASHMIR | M14: 19 | N14: Udhampur | P14: 1 | Q14: Jammu & Kashmir | R14: 14 | S14: Anantnag
... A653: 33 | B653: TAMIL NADU | C653: 31 | D653: Coimbatore | F653: 33 | G653: TAMIL NADU | H653: 31 | I653: Coimbatore | K653: 33 | L653: TAMIL NADU | M653: 29 | N653: Dharmapuri | P653: 36 | Q653: Telangana | R653: 10 | S653: Khammam
A654: 33 | B654: TAMIL NADU | C654: 32 | D654: Tiruppur | F654: 33 | G654: TAMIL NADU | H654: 32 | I654: Tiruppur | K654: 33 | L654: TAMIL NADU | M654: 30 | N654: Krishnagiri
A655: 34 | B655: PUDUCHERRY | C655: 1 | D655: Yanam | F655: 34 | G655: PUDUCHERRY | H655: 1 | I655: Yanam | K655: 33 | L655: TAMIL NADU | M655: 31 | N655: Coimbatore
A656: 34 | B656: PUDUCHERRY | C656: 2 | D656: Puducherry | F656: 34 | G656: PUDUCHERRY | H656: 2 | I656: Puducherry | K656: 33 | L656: TAMIL NADU | M656: 32 | N656: Tiruppur
A657: 34 | B657: PUDUCHERRY | C657: 3 | D657: Mahe | F657: 34 | G657: PUDUCHERRY | H657: 3 | I657: Mahe | K657: 34 | L657: PUDUCHERRY | M657: 1 | N657: Yanam
A658: 34 | B658: PUDUCHERRY | C658: 4 | D658: Karaikal | F658: 34 | G658: PUDUCHERRY | H658: 4 | I658: Karaikal | K658: 34 | L658: PUDUCHERRY | M658: 2 | N658: Puducherry
A659: 35 | B659: A & N ISLANDS | C659: 1 | D659: Nicobars | F659: 35 | G659: A & N ISLANDS | H659: 1 | I659: Nicobars | K659: 34 | L659: PUDUCHERRY | M659: 3 | N659: Mahe
A660: 35 | B660: A & N ISLANDS | C660: 2 | D660: North & Middle Andaman | F660: 35 | G660: A & N ISLANDS | H660: 2 | I660: North & Middle Andaman | K660: 34 | L660: PUDUCHERRY | M660: 4 | N660: Karaikal
A661: 35 | B661: A & N ISLANDS | C661: 3 | D661: South Andaman | F661: 35 | G661: A & N ISLANDS | H661: 3 | I661: South Andaman | K661: 35 | L661: A & N ISLANDS | M661: 1 | N661: Nicobars
A662: 36 | B662: TELANGANA | C662: 1 | D662: Adilabad | F662: 36 | G662: TELANGANA | H662: 1 | I662: Adilabad | K662: 35 | L662: A & N ISLANDS | M662: 2 | N662: North & Middle Andaman
A663: 36 | B663: TELANGANA | C663: 2 | D663: Komaram Bheem | F663: 36 | G663: TELANGANA | H663: 2 | I663: Komaram Bheem | K663: 35 | L663: A & N ISLANDS | M663: 3 | N663: South Andaman
A664: 36 | B664: TELANGANA | C664: 3 | D664: Mancherial | F664: 36 | G664: TELANGANA | H664: 3 | I664: Mancherial | K664: 36 | L664: TELANGANA | M664: 1 | N664: Adilabad
A665: 36 | B665: TELANGANA | C665: 4 | D665: Nirmal | F665: 36 | G665: TELANGANA | H665: 4 | I665: Nirmal | K665: 36 | L665: TELANGANA | M665: 2 | N665: Komaram Bheem
... A696: 37 | B696: LADAKH | C696: 2 | D696: Kargil | F696: 37 | G696: LADAKH | H696: 2 | I696: Kargil | K696: 36 | L696: TELANGANA | M696: 33 | N696: Narayanpet

Sheet State Names
A1: 17-19 Code | B1: 17-19 Name | D1: 19-21 Code | E1: 19-21 Name | G1: 21-23 Code | H1: 21-23 Name | J1: 23-24 Code | K1: 23-24 Name | M1: 2025 Code | N1: 2025 Name | P1: State Code | Q1: 17-19 Name | R1: 19-21 Name | S1: 21-23 Name | T1: 23-24 Name | U1: 2025 Name | V1: Changed?
A2: {=_xlfn._xlws.SORT(_xlfn.UNIQUE(_xlfn._xlws.FILTER('Raw Data'!U4:V1001,'Raw Data'!U4:U1001<>"")),1,1)} -> #VALUE! | D2: {=_xlfn._xlws.SORT(_xlfn.UNIQUE(_xlfn._xlws.FILTER('Raw Data'!P5:Q1001,'Raw Data'!P5:P1001<>"")),1,1)} -> 1 | E2: Jammu & Kashmir | G2: {=_xlfn._xlws.SORT(_xlfn.UNIQUE(_xlfn._xlws.FILTER('Raw Data'!K5:L1001,'Raw Data'!K5:K1001<>"")),1,1)} -> 1 | H2: JAMMU & KASHMIR | J2: {=_xlfn._xlws.SORT(_xlfn.UNIQUE(_xlfn._xlws.FILTER('Raw Data'!F5:G1001,'Raw Data'!F5:F1001<>"")),1,1)} -> 1 | K2: JAMMU & KASHMIR | M2: {=_xlfn._xlws.SORT(_xlfn.UNIQUE(_xlfn._xlws.FILTER('Raw Data'!A699:B1001,'Raw Data'!A699:A1001<>"")),1,1)} -> #VALUE! | P2: {=_xlfn.LET(_xlpm.x,_xlfn.VSTACK(A2:A100,D2:D100,G2:G100,J2:J100,M2:M100),_xlfn._xlws.SORT(_xlfn.UNIQUE(_xlfn._xlws.FILTER(_xlpm.x,_xlpm.x<>""))))} -> #VALUE! | Q2: =_xlfn.XLOOKUP(P2,$A$2:$A$100,$B$2:$B$100,"") -> #VALUE! | R2: =_xlfn.XLOOKUP(P2,$D$2:$D$100,$E$2:$E$100,"") -> #VALUE! | S2: =_xlfn.XLOOKUP(P2,$G$2:$G$100,$H$2:$H$100,"") -> #VALUE! | T2: =_xlfn.XLOOKUP(P2,$J$2:$J$100,$K$2:$K$100,"") -> #VALUE! | U2: =_xlfn.XLOOKUP(P2,$M$2:$M$100,$N$2:$N$100,"") -> #VALUE! | V2: No
D3: 2 | E3: Himachal Pradesh | G3: 2 | H3: HIMACHAL PRADESH | J3: 2 | K3: HIMACHAL PRADESH | Q3: =_xlfn.XLOOKUP(P3,$A$2:$A$100,$B$2:$B$100,"") -> 0 | R3: =_xlfn.XLOOKUP(P3,$D$2:$D$100,$E$2:$E$100,"") -> 0 | S3: =_xlfn.XLOOKUP(P3,$G$2:$G$100,$H$2:$H$100,"") -> 0 | T3: =_xlfn.XLOOKUP(P3,$J$2:$J$100,$K$2:$K$100,"") -> 0 | U3: =_xlfn.XLOOKUP(P3,$M$2:$M$100,$N$2:$N$100,"") -> 0 | V3: =IF(AND( LOWER(TRIM(Q3))=LOWER(TRIM(R3)), LOWER(TRIM(R3))=LOWER(TRIM(S3)), LOWER(TRIM(S3))=LOWER(TRIM(T3)), LOWER(TRIM(T3))=LOWER(TRIM(U3)) ),"No","YES") -> No
D4: 3 | E4: Punjab | G4: 3 | H4: PUNJAB | J4: 3 | K4: PUNJAB | Q4: =_xlfn.XLOOKUP(P4,$A$2:$A$100,$B$2:$B$100,"") -> 0 | R4: =_xlfn.XLOOKUP(P4,$D$2:$D$100,$E$2:$E$100,"") -> 0 | S4: =_xlfn.XLOOKUP(P4,$G$2:$G$100,$H$2:$H$100,"") -> 0 | T4: =_xlfn.XLOOKUP(P4,$J$2:$J$100,$K$2:$K$100,"") -> 0 | U4: =_xlfn.XLOOKUP(P4,$M$2:$M$100,$N$2:$N$100,"") -> 0 | V4: =IF(AND( LOWER(TRIM(Q4))=LOWER(TRIM(R4)), LOWER(TRIM(R4))=LOWER(TRIM(S4)), LOWER(TRIM(S4))=LOWER(TRIM(T4)), LOWER(TRIM(T4))=LOWER(TRIM(U4)) ),"No","YES") -> No
D5: 4 | E5: Chandigarh | G5: 4 | H5: CHANDIGARH | J5: 4 | K5: CHANDIGARH | Q5: =_xlfn.XLOOKUP(P5,$A$2:$A$100,$B$2:$B$100,"") -> 0 | R5: =_xlfn.XLOOKUP(P5,$D$2:$D$100,$E$2:$E$100,"") -> 0 | S5: =_xlfn.XLOOKUP(P5,$G$2:$G$100,$H$2:$H$100,"") -> 0 | T5: =_xlfn.XLOOKUP(P5,$J$2:$J$100,$K$2:$K$100,"") -> 0 | U5: =_xlfn.XLOOKUP(P5,$M$2:$M$100,$N$2:$N$100,"") -> 0 | V5: =IF(AND( LOWER(TRIM(Q5))=LOWER(TRIM(R5)), LOWER(TRIM(R5))=LOWER(TRIM(S5)), LOWER(TRIM(S5))=LOWER(TRIM(T5)), LOWER(TRIM(T5))=LOWER(TRIM(U5)) ),"No","YES") -> No
D6: 5 | E6: Uttarakhand | G6: 5 | H6: UTTARAKHAND | J6: 5 | K6: UTTARAKHAND | Q6: =_xlfn.XLOOKUP(P6,$A$2:$A$100,$B$2:$B$100,"") -> 0 | R6: =_xlfn.XLOOKUP(P6,$D$2:$D$100,$E$2:$E$100,"") -> 0 | S6: =_xlfn.XLOOKUP(P6,$G$2:$G$100,$H$2:$H$100,"") -> 0 | T6: =_xlfn.XLOOKUP(P6,$J$2:$J$100,$K$2:$K$100,"") -> 0 | U6: =_xlfn.XLOOKUP(P6,$M$2:$M$100,$N$2:$N$100,"") -> 0 | V6: =IF(AND( LOWER(TRIM(Q6))=LOWER(TRIM(R6)), LOWER(TRIM(R6))=LOWER(TRIM(S6)), LOWER(TRIM(S6))=LOWER(TRIM(T6)), LOWER(TRIM(T6))=LOWER(TRIM(U6)) ),"No","YES") -> No
D7: 6 | E7: Haryana | G7: 6 | H7: HARYANA | J7: 6 | K7: HARYANA | Q7: =_xlfn.XLOOKUP(P7,$A$2:$A$100,$B$2:$B$100,"") -> 0 | R7: =_xlfn.XLOOKUP(P7,$D$2:$D$100,$E$2:$E$100,"") -> 0 | S7: =_xlfn.XLOOKUP(P7,$G$2:$G$100,$H$2:$H$100,"") -> 0 | T7: =_xlfn.XLOOKUP(P7,$J$2:$J$100,$K$2:$K$100,"") -> 0 | U7: =_xlfn.XLOOKUP(P7,$M$2:$M$100,$N$2:$N$100,"") -> 0 | V7: =IF(AND( LOWER(TRIM(Q7))=LOWER(TRIM(R7)), LOWER(TRIM(R7))=LOWER(TRIM(S7)), LOWER(TRIM(S7))=LOWER(TRIM(T7)), LOWER(TRIM(T7))=LOWER(TRIM(U7)) ),"No","YES") -> No
D8: 7 | E8: Delhi | G8: 7 | H8: DELHI | J8: 7 | K8: DELHI | Q8: =_xlfn.XLOOKUP(P8,$A$2:$A$100,$B$2:$B$100,"") -> 0 | R8: =_xlfn.XLOOKUP(P8,$D$2:$D$100,$E$2:$E$100,"") -> 0 | S8: =_xlfn.XLOOKUP(P8,$G$2:$G$100,$H$2:$H$100,"") -> 0 | T8: =_xlfn.XLOOKUP(P8,$J$2:$J$100,$K$2:$K$100,"") -> 0 | U8: =_xlfn.XLOOKUP(P8,$M$2:$M$100,$N$2:$N$100,"") -> 0 | V8: =IF(AND( LOWER(TRIM(Q8))=LOWER(TRIM(R8)), LOWER(TRIM(R8))=LOWER(TRIM(S8)), LOWER(TRIM(S8))=LOWER(TRIM(T8)), LOWER(TRIM(T8))=LOWER(TRIM(U8)) ),"No","YES") -> No
D9: 8 | E9: Rajasthan | G9: 8 | H9: RAJASTHAN | J9: 8 | K9: RAJASTHAN | Q9: =_xlfn.XLOOKUP(P9,$A$2:$A$100,$B$2:$B$100,"") -> 0 | R9: =_xlfn.XLOOKUP(P9,$D$2:$D$100,$E$2:$E$100,"") -> 0 | S9: =_xlfn.XLOOKUP(P9,$G$2:$G$100,$H$2:$H$100,"") -> 0 | T9: =_xlfn.XLOOKUP(P9,$J$2:$J$100,$K$2:$K$100,"") -> 0 | U9: =_xlfn.XLOOKUP(P9,$M$2:$M$100,$N$2:$N$100,"") -> 0 | V9: =IF(AND( LOWER(TRIM(Q9))=LOWER(TRIM(R9)), LOWER(TRIM(R9))=LOWER(TRIM(S9)), LOWER(TRIM(S9))=LOWER(TRIM(T9)), LOWER(TRIM(T9))=LOWER(TRIM(U9)) ),"No","YES") -> No
D10: 9 | E10: Uttar Pradesh | G10: 9 | H10: UTTAR PRADESH | J10: 9 | K10: UTTAR PRADESH | Q10: =_xlfn.XLOOKUP(P10,$A$2:$A$100,$B$2:$B$100,"") -> 0 | R10: =_xlfn.XLOOKUP(P10,$D$2:$D$100,$E$2:$E$100,"") -> 0 | S10: =_xlfn.XLOOKUP(P10,$G$2:$G$100,$H$2:$H$100,"") -> 0 | T10: =_xlfn.XLOOKUP(P10,$J$2:$J$100,$K$2:$K$100,"") -> 0 | U10: =_xlfn.XLOOKUP(P10,$M$2:$M$100,$N$2:$N$100,"") -> 0 | V10: =IF(AND( LOWER(TRIM(Q10))=LOWER(TRIM(R10)), LOWER(TRIM(R10))=LOWER(TRIM(S10)), LOWER(TRIM(S10))=LOWER(TRIM(T10)), LOWER(TRIM(T10))=LOWER(TRIM(U10)) ),"No","YES") -> No
D11: 10 | E11: Bihar | G11: 10 | H11: BIHAR | J11: 10 | K11: BIHAR | Q11: =_xlfn.XLOOKUP(P11,$A$2:$A$100,$B$2:$B$100,"") -> 0 | R11: =_xlfn.XLOOKUP(P11,$D$2:$D$100,$E$2:$E$100,"") -> 0 | S11: =_xlfn.XLOOKUP(P11,$G$2:$G$100,$H$2:$H$100,"") -> 0 | T11: =_xlfn.XLOOKUP(P11,$J$2:$J$100,$K$2:$K$100,"") -> 0 | U11: =_xlfn.XLOOKUP(P11,$M$2:$M$100,$N$2:$N$100,"") -> 0 | V11: =IF(AND( LOWER(TRIM(Q11))=LOWER(TRIM(R11)), LOWER(TRIM(R11))=LOWER(TRIM(S11)), LOWER(TRIM(S11))=LOWER(TRIM(T11)), LOWER(TRIM(T11))=LOWER(TRIM(U11)) ),"No","YES") -> No
D12: 11 | E12: Sikkim | G12: 11 | H12: SIKKIM | J12: 11 | K12: SIKKIM | Q12: =_xlfn.XLOOKUP(P12,$A$2:$A$100,$B$2:$B$100,"") -> 0 | R12: =_xlfn.XLOOKUP(P12,$D$2:$D$100,$E$2:$E$100,"") -> 0 | S12: =_xlfn.XLOOKUP(P12,$G$2:$G$100,$H$2:$H$100,"") -> 0 | T12: =_xlfn.XLOOKUP(P12,$J$2:$J$100,$K$2:$K$100,"") -> 0 | U12: =_xlfn.XLOOKUP(P12,$M$2:$M$100,$N$2:$N$100,"") -> 0 | V12: =IF(AND( LOWER(TRIM(Q12))=LOWER(TRIM(R12)), LOWER(TRIM(R12))=LOWER(TRIM(S12)), LOWER(TRIM(S12))=LOWER(TRIM(T12)), LOWER(TRIM(T12))=LOWER(TRIM(U12)) ),"No","YES") -> No
D13: 12 | E13: Arunachal Pradesh | G13: 12 | H13: ARUNACHAL PRADESH | J13: 12 | K13: ARUNACHAL PRADESH | Q13: =_xlfn.XLOOKUP(P13,$A$2:$A$100,$B$2:$B$100,"") -> 0 | R13: =_xlfn.XLOOKUP(P13,$D$2:$D$100,$E$2:$E$100,"") -> 0 | S13: =_xlfn.XLOOKUP(P13,$G$2:$G$100,$H$2:$H$100,"") -> 0 | T13: =_xlfn.XLOOKUP(P13,$J$2:$J$100,$K$2:$K$100,"") -> 0 | U13: =_xlfn.XLOOKUP(P13,$M$2:$M$100,$N$2:$N$100,"") -> 0 | V13: =IF(AND( LOWER(TRIM(Q13))=LOWER(TRIM(R13)), LOWER(TRIM(R13))=LOWER(TRIM(S13)), LOWER(TRIM(S13))=LOWER(TRIM(T13)), LOWER(TRIM(T13))=LOWER(TRIM(U13)) ),"No","YES") -> No
D14: 13 | E14: Nagaland | G14: 13 | H14: NAGALAND | J14: 13 | K14: NAGALAND | Q14: =_xlfn.XLOOKUP(P14,$A$2:$A$100,$B$2:$B$100,"") -> 0 | R14: =_xlfn.XLOOKUP(P14,$D$2:$D$100,$E$2:$E$100,"") -> 0 | S14: =_xlfn.XLOOKUP(P14,$G$2:$G$100,$H$2:$H$100,"") -> 0 | T14: =_xlfn.XLOOKUP(P14,$J$2:$J$100,$K$2:$K$100,"") -> 0 | U14: =_xlfn.XLOOKUP(P14,$M$2:$M$100,$N$2:$N$100,"") -> 0 | V14: =IF(AND( LOWER(TRIM(Q14))=LOWER(TRIM(R14)), LOWER(TRIM(R14))=LOWER(TRIM(S14)), LOWER(TRIM(S14))=LOWER(TRIM(T14)), LOWER(TRIM(T14))=LOWER(TRIM(U14)) ),"No","YES") -> No
... D35: 34 | E35: Puducherry | G35: 34 | H35: PUDUCHERRY | J35: 35 | K35: A & N ISLANDS | Q35: =_xlfn.XLOOKUP(P35,$A$2:$A$100,$B$2:$B$100,"") -> 0 | R35: =_xlfn.XLOOKUP(P35,$D$2:$D$100,$E$2:$E$100,"") -> 0 | S35: =_xlfn.XLOOKUP(P35,$G$2:$G$100,$H$2:$H$100,"") -> 0 | T35: =_xlfn.XLOOKUP(P35,$J$2:$J$100,$K$2:$K$100,"") -> 0 | U35: =_xlfn.XLOOKUP(P35,$M$2:$M$100,$N$2:$N$100,"") -> 0 | V35: =IF(AND( LOWER(TRIM(Q35))=LOWER(TRIM(R35)), LOWER(TRIM(R35))=LOWER(TRIM(S35)), LOWER(TRIM(S35))=LOWER(TRIM(T35)), LOWER(TRIM(T35))=LOWER(TRIM(U35)) ),"No","YES") -> No
D36: 35 | E36: A & N Islands | G36: 35 | H36: A & N ISLANDS | J36: 36 | K36: TELANGANA | Q36: =_xlfn.XLOOKUP(P36,$A$2:$A$100,$B$2:$B$100,"") -> 0 | R36: =_xlfn.XLOOKUP(P36,$D$2:$D$100,$E$2:$E$100,"") -> 0 | S36: =_xlfn.XLOOKUP(P36,$G$2:$G$100,$H$2:$H$100,"") -> 0 | T36: =_xlfn.XLOOKUP(P36,$J$2:$J$100,$K$2:$K$100,"") -> 0 | U36: =_xlfn.XLOOKUP(P36,$M$2:$M$100,$N$2:$N$100,"") -> 0 | V36: No
D37: 36 | E37: Telangana | G37: 36 | H37: TELANGANA | J37: 37 | K37: LADAKH | Q37: =_xlfn.XLOOKUP(P37,$A$2:$A$100,$B$2:$B$100,"") -> 0 | R37: =_xlfn.XLOOKUP(P37,$D$2:$D$100,$E$2:$E$100,"") -> 0 | S37: =_xlfn.XLOOKUP(P37,$G$2:$G$100,$H$2:$H$100,"") -> 0 | T37: =_xlfn.XLOOKUP(P37,$J$2:$J$100,$K$2:$K$100,"") -> 0 | U37: =_xlfn.XLOOKUP(P37,$M$2:$M$100,$N$2:$N$100,"") -> 0 | V37: =IF(AND( LOWER(TRIM(Q37))=LOWER(TRIM(R37)), LOWER(TRIM(R37))=LOWER(TRIM(S37)), LOWER(TRIM(S37))=LOWER(TRIM(T37)), LOWER(TRIM(T37))=LOWER(TRIM(U37)) ),"No","YES") -> No
Q38: =_xlfn.XLOOKUP(P38,$A$2:$A$100,$B$2:$B$100,"") -> 0 | R38: =_xlfn.XLOOKUP(P38,$D$2:$D$100,$E$2:$E$100,"") -> 0 | S38: =_xlfn.XLOOKUP(P38,$G$2:$G$100,$H$2:$H$100,"") -> 0 | T38: =_xlfn.XLOOKUP(P38,$J$2:$J$100,$K$2:$K$100,"") -> 0 | U38: =_xlfn.XLOOKUP(P38,$M$2:$M$100,$N$2:$N$100,"") -> 0 | V38: No
